Workbook

Sheet Dashboard
A1: PRODUCT SALES REGION - ADVANCED 5.2 FIXED AUDITED | Plain Range Formulas Data!B2:B1501 - No Structured Ref = No #REF! | 15 Charts | Full Screen Alt+W+L
A3: Total Revenue | D3: Total Qty | G3: Avg Discount | J3: Return Rate | M3: Total Orders | P3: ⛶ FULL SCREEN (Alt+W+L)
A4: =SUM(Data!J2:J1501) | D4: =SUM(Data!D2:D1501) | G4: =AVERAGE(Data!H2:H1501) | J4: =SUM(Data!M2:M1501)/COUNTA(Data!M2:M1501) | M4: =COUNTA(Data!N2:N1501) | P4: Go to Data | Q4: Go to Analytics

Sheet Data
A1: Date | B1: Region | C1: Product | D1: Quantity | E1: UnitPrice | F1: StoreLocation | G1: CustomerType | H1: Discount | I1: Salesperson | J1: TotalPrice | K1: PaymentMethod | L1: Promotion | M1: Returned | N1: OrderID | O1: CustomerName | P1: ShippingCost | Q1: OrderDate | R1: DeliveryDate | S1: RegionManager | T1: YearMonth
A2: 44980 | B2: East | C2: Laptop | D2: 14 | E2: 163.6 | F2: Store B | G2: Wholesale | H2: 0 | I2: Eva | J2: 2290.4 | K2: Online | L2: FREESHIP | M2: 0 | N2: REG100000 | O2: Cust 6583 | P2: 43.34 | Q2: 44980 | R2: 44984 | S2: Eric | T2: 2023-02
A3: 45645 | B3: South | C3: Phone | D3: 1 | E3: 544.01 | F3: Store A | G3: Retail | H3: 0 | I3: Alice | J3: 544.01 | K3: Gift Card | L3: SAVE10 | M3: 0 | N3: REG100001 | O3: Cust 2144 | P3: 5.3 | Q3: 45645 | R3: 45654 | S3: Sophie | T3: 2024-12
A4: 45056 | B4: North | C4: Desk | D4: 14 | E4: 346.18 | F4: Store B | G4: Wholesale | H4: 0.1 | I4: Alice | J4: 4361.868 | K4: Online | L4: WINTER15 | M4: 0 | N4: REG100002 | O4: Cust 5998 | P4: 20.46 | Q4: 45056 | R4: 45065 | S4: Ryan | T4: 2023-05
A5: 45714 | B5: Central | C5: Chair | D5: 18 | E5: 384.82 | F5: Store A | G5: Wholesale | H5: 0.15 | I5: Frank | J5: 5887.746 | K5: Gift Card | L5: FREESHIP | M5: 0 | N5: REG100003 | O5: Cust 7136 | P5: 27.95 | Q5: 45714 | R5: 45718 | S5: Cameron | T5: 2025-02
A6: 45101 | B6: East | C6: Desk | D6: 18 | E6: 237.76 | F6: Store C | G6: Retail | H6: 0 | I6: Carlos | J6: 4279.68 | K6: Online | L6: SAVE10 | M6: 0 | N6: REG100004 | O6: Cust 6506 | P6: 5.73 | Q6: 45101 | R6: 45104 | S6: Eric | T6: 2023-06
A7: 45342 | B7: Central | C7: Monitor | D7: 2 | E7: 385.09 | F7: Store D | G7: Wholesale | H7: 0.15 | I7: Diana | J7: 654.653 | K7: Credit Card | M7: 0 | N7: REG100005 | O7: Cust 3909 | P7: 11.92 | Q7: 45342 | R7: 45352 | S7: Cameron | T7: 2024-02
A8: 44937 | B8: South | C8: Chair | D8: 7 | E8: 17.5 | F8: Store C | G8: Retail | H8: 0.1 | I8: Alice | J8: 110.25 | K8: Debit Card | L8: WINTER15 | M8: 0 | N8: REG100006 | O8: Cust 7887 | P8: 5.02 | Q8: 44937 | R8: 44940 | S8: Sophie | T8: 2023-01
A9: 44935 | B9: Central | C9: Chair | D9: 3 | E9: 330.22 | F9: Store C | G9: Wholesale | H9: 0.15 | I9: Carlos | J9: 842.061 | K9: Cash | M9: 0 | N9: REG100007 | O9: Cust 5301 | P9: 48.01 | Q9: 44935 | R9: 44937 | S9: Cameron | T9: 2023-01
A10: 45581 | B10: South | C10: Chair | D10: 3 | E10: 432.04 | F10: Store D | G10: Wholesale | H10: 0.05 | I10: Bob | J10: 1231.314 | K10: Debit Card | L10: FREESHIP | M10: 1 | N10: REG100008 | O10: Cust 2284 | P10: 42.11 | Q10: 45581 | R10: 45583 | S10: Sophie | T10: 2024-10
A11: 45721 | B11: West | C11: Desk | D11: 5 | E11: 323.28 | F11: Store D | G11: Retail | H11: 0.1 | I11: Frank | J11: 1454.76 | K11: Gift Card | L11: SAVE10 | M11: 0 | N11: REG100009 | O11: Cust 3732 | P11: 41.1 | Q11: 45721 | R11: 45729 | S11: Wendy | T11: 2025-03
A12: 45392 | B12: North | C12: Desk | D12: 15 | E12: 523.29 | F12: Store B | G12: Wholesale | H12: 0.15 | I12: Eva | J12: 6671.9475 | K12: Debit Card | M12: 0 | N12: REG100010 | O12: Cust 1462 | P12: 12.14 | Q12: 45392 | R12: 45399 | S12: Ryan | T12: 2024-04
A13: 45485 | B13: East | C13: Phone | D13: 19 | E13: 207.35 | F13: Store D | G13: Retail | H13: 0.1 | I13: Eva | J13: 3545.685 | K13: Gift Card | M13: 1 | N13: REG100011 | O13: Cust 4330 | P13: 44.89 | Q13: 45485 | R13: 45491 | S13: Eric | T13: 2024-07
A14: 45128 | B14: Central | C14: Phone | D14: 1 | E14: 120.53 | F14: Store B | G14: Retail | H14: 0.05 | I14: Diana | J14: 114.5035 | K14: Cash | L14: WINTER15 | M14: 0 | N14: REG100012 | O14: Cust 2372 | P14: 20.35 | Q14: 45128 | R14: 45138 | S14: Cameron | T14: 2023-07
A15: 45675 | B15: West | C15: Tablet | D15: 1 | E15: 157.83 | F15: Store A | G15: Wholesale | H15: 0.15 | I15: Carlos | J15: 134.1555 | K15: Debit Card | M15: 0 | N15: REG100013 | O15: Cust 4672 | P15: 42.82 | Q15: 45675 | R15: 45679 | S15: Wendy | T15: 2025-01
A16: 45634 | B16: North | C16: Desk | D16: 15 | E16: 220.3 | F16: Store B | G16: Retail | H16: 0.15 | I16: Diana | J16: 2808.825 | K16: Debit Card | M16: 0 | N16: REG100014 | O16: Cust 4548 | P16: 39.66 | Q16: 45634 | R16: 45641 | S16: Ryan | T16: 2024-12
A17: 45788 | B17: West | C17: Chair | D17: 17 | E17: 162.96 | F17: Store A | G17: Wholesale | H17: 0.05 | I17: Eva | J17: 2631.804 | K17: Gift Card | L17: FREESHIP | M17: 0 | N17: REG100015 | O17: Cust 7037 | P17: 8.11 | Q17: 45788 | R17: 45794 | S17: Wendy | T17: 2025-05
A18: 44983 | B18: West | C18: Laptop | D18: 19 | E18: 236.11 | F18: Store D | G18: Wholesale | H18: 0 | I18: Bob | J18: 4486.09 | K18: Online | L18: WINTER15 | M18: 0 | N18: REG100016 | O18: Cust 4975 | P18: 34.11 | Q18: 44983 | R18: 44989 | S18: Wendy | T18: 2023-02
A19: 45440 | B19: Central | C19: Desk | D19: 11 | E19: 573.14 | F19: Store D | G19: Retail | H19: 0.05 | I19: Diana | J19: 5989.313 | K19: Cash | L19: SAVE10 | M19: 0 | N19: REG100017 | O19: Cust 8014 | P19: 34.71 | Q19: 45440 | R19: 45444 | S19: Cameron | T19: 2024-05
A20: 45260 | B20: East | C20: Phone | D20: 20 | E20: 519.04 | F20: Store B | G20: Retail | H20: 0.15 | I20: Carlos | J20: 8823.68 | K20: Gift Card | L20: FREESHIP | M20: 0 | N20: REG100018 | O20: Cust 1228 | P20: 19.43 | Q20: 45260 | R20: 45268 | S20: Eric | T20: 2023-11
A21: 45099 | B21: West | C21: Desk | D21: 14 | E21: 30.83 | F21: Store B | G21: Retail | H21: 0 | I21: Carlos | J21: 431.62 | K21: Online | L21: WINTER15 | M21: 1 | N21: REG100019 | O21: Cust 4247 | P21: 7.1 | Q21: 45099 | R21: 45109 | S21: Wendy | T21: 2023-06
A22: 45813 | B22: West | C22: Phone | D22: 10 | E22: 319.05 | F22: Store D | G22: Wholesale | H22: 0 | I22: Diana | J22: 3190.5 | K22: Online | M22: 0 | N22: REG100020 | O22: Cust 4199 | P22: 28.43 | Q22: 45813 | R22: 45816 | S22: Wendy | T22: 2025-06
A23: 44988 | B23: Central | C23: Chair | D23: 14 | E23: 312.79 | F23: Store A | G23: Retail | H23: 0.05 | I23: Bob | J23: 4160.107 | K23: Online | M23: 1 | N23: REG100021 | O23: Cust 4186 | P23: 46.83 | Q23: 44988 | R23: 44993 | S23: Cameron | T23: 2023-03
A24: 45340 | B24: North | C24: Laptop | D24: 14 | E24: 395.45 | F24: Store C | G24: Retail | H24: 0 | I24: Carlos | J24: 5536.3 | K24: Cash | L24: FREESHIP | M24: 1 | N24: REG100022 | O24: Cust 8137 | P24: 36.45 | Q24: 45340 | R24: 45344 | S24: Ryan | T24: 2024-02
A25: 45144 | B25: Central | C25: Laptop | D25: 12 | E25: 472.72 | F25: Store D | G25: Retail | H25: 0.15 | I25: Diana | J25: 4821.744 | K25: Credit Card | M25: 0 | N25: REG100023 | O25: Cust 4638 | P25: 27.97 | Q25: 45144 | R25: 45152 | S25: Cameron | T25: 2023-08
A26: 45435 | B26: North | C26: Desk | D26: 5 | E26: 288.01 | F26: Store A | G26: Wholesale | H26: 0 | I26: Eva | J26: 1440.05 | K26: Credit Card | L26: FREESHIP | M26: 0 | N26: REG100024 | O26: Cust 8538 | P26: 46.69 | Q26: 45435 | R26: 45442 | S26: Ryan | T26: 2024-05
A27: 45222 | B27: East | C27: Phone | D27: 13 | E27: 562.29 | F27: Store D | G27: Retail | H27: 0 | I27: Diana | J27: 7309.77 | K27: Gift Card | L27: SAVE10 | M27: 0 | N27: REG100025 | O27: Cust 6322 | P27: 38.13 | Q27: 45222 | R27: 45227 | S27: Eric | T27: 2023-10
A28: 45824 | B28: West | C28: Phone | D28: 1 | E28: 101.73 | F28: Store D | G28: Retail | H28: 0 | I28: Frank | J28: 101.73 | K28: Debit Card | L28: WINTER15 | M28: 0 | N28: REG100026 | O28: Cust 2609 | P28: 11.59 | Q28: 45824 | R28: 45833 | S28: Wendy | T28: 2025-06
A29: 44988 | B29: North | C29: Phone | D29: 4 | E29: 279.49 | F29: Store B | G29: Retail | H29: 0 | I29: Diana | J29: 1117.96 | K29: Credit Card | L29: FREESHIP | M29: 0 | N29: REG100027 | O29: Cust 6880 | P29: 24.78 | Q29: 44988 | R29: 44993 | S29: Ryan | T29: 2023-03
A30: 45614 | B30: South | C30: Laptop | D30: 1 | E30: 178.55 | F30: Store A | G30: Retail | H30: 0.15 | I30: Carlos | J30: 151.7675 | K30: Debit Card | L30: SAVE10 | M30: 1 | N30: REG100028 | O30: Cust 1997 | P30: 7.61 | Q30: 45614 | R30: 45617 | S30: Sophie | T30: 2024-11
A31: 45055 | B31: Central | C31: Tablet | D31: 1 | E31: 472.07 | F31: Store A | G31: Wholesale | H31: 0.1 | I31: Carlos | J31: 424.863 | K31: Online | L31: FREESHIP | M31: 0 | N31: REG100029 | O31: Cust 7072 | P31: 33.17 | Q31: 45055 | R31: 45063 | S31: Cameron | T31: 2023-05
A32: 45633 | B32: North | C32: Tablet | D32: 12 | E32: 306.29 | F32: Store D | G32: Retail | H32: 0 | I32: Frank | J32: 3675.48 | K32: Debit Card | L32: SAVE10 | M32: 0 | N32: REG100030 | O32: Cust 7201 | P32: 37.38 | Q32: 45633 | R32: 45640 | S32: Ryan | T32: 2024-12
A33: 45335 | B33: North | C33: Phone | D33: 7 | E33: 434.77 | F33: Store C | G33: Retail | H33: 0.15 | I33: Frank | J33: 2586.8815 | K33: Online | L33: SAVE10 | M33: 0 | N33: REG100031 | O33: Cust 9923 | P33: 12.35 | Q33: 45335 | R33: 45337 | S33: Ryan | T33: 2024-02
A34: 45725 | B34: South | C34: Desk | D34: 6 | E34: 64.98 | F34: Store C | G34: Retail | H34: 0 | I34: Carlos | J34: 389.88 | K34: Debit Card | L34: WINTER15 | M34: 0 | N34: REG100032 | O34: Cust 2205 | P34: 21.25 | Q34: 45725 | R34: 45731 | S34: Sophie | T34: 2025-03
A35: 45021 | B35: Central | C35: Desk | D35: 17 | E35: 476.49 | F35: Store D | G35: Retail | H35: 0 | I35: Alice | J35: 8100.33 | K35: Gift Card | M35: 0 | N35: REG100033 | O35: Cust 6403 | P35: 17.91 | Q35: 45021 | R35: 45027 | S35: Cameron | T35: 2023-04
A36: 45785 | B36: North | C36: Monitor | D36: 4 | E36: 559.72 | F36: Store D | G36: Retail | H36: 0.15 | I36: Diana | J36: 1903.048 | K36: Online | L36: SAVE10 | M36: 0 | N36: REG100034 | O36: Cust 3953 | P36: 41.91 | Q36: 45785 | R36: 45789 | S36: Ryan | T36: 2025-05
A37: 45172 | B37: North | C37: Tablet | D37: 14 | E37: 82.14 | F37: Store C | G37: Retail | H37: 0 | I37: Alice | J37: 1149.96 | K37: Credit Card | M37: 0 | N37: REG100035 | O37: Cust 7902 | P37: 12.57 | Q37: 45172 | R37: 45180 | S37: Ryan | T37: 2023-09
A38: 45737 | B38: Central | C38: Chair | D38: 9 | E38: 343.21 | F38: Store A | G38: Retail | H38: 0.05 | I38: Carlos | J38: 2934.4455 | K38: Debit Card | L38: FREESHIP | M38: 0 | N38: REG100036 | O38: Cust 9968 | P38: 40.29 | Q38: 45737 | R38: 45744 | S38: Cameron | T38: 2025-03
A39: 45828 | B39: South | C39: Chair | D39: 7 | E39: 301.01 | F39: Store B | G39: Retail | H39: 0.15 | I39: Diana | J39: 1791.0095 | K39: Cash | L39: SAVE10 | M39: 1 | N39: REG100037 | O39: Cust 3787 | P39: 34.97 | Q39: 45828 | R39: 45838 | S39: Sophie | T39: 2025-06
A40: 45337 | B40: Central | C40: Printer | D40: 14 | E40: 428.13 | F40: Store C | G40: Retail | H40: 0.1 | I40: Bob | J40: 5394.438 | K40: Cash | M40: 1 | N40: REG100038 | O40: Cust 2469 | P40: 24.77 | Q40: 45337 | R40: 45347 | S40: Cameron | T40: 2024-02
...

Sheet Analytics
A1: 1. Sales by Region - X=Region Y=SUM(TotalPrice) | D1: 2. Product X=Product Y=Sales | G1: 3. Customer X=Type Y=Qty | J1: 4. Payment X=Payment Y=Sales
A2: Region | B2: Total Sales | D2: Product | E2: Sales | G2: CustomerType | H2: Qty | J2: Payment | K2: Sales
A3: Central | B3: =SUMIF(Data!$B$2:$B$1501,"Central",Data!$J$2:$J$1501) | D3: Chair | E3: =SUMIF(Data!$C$2:$C$1501,"Chair",Data!$J$2:$J$1501) | G3: Retail | H3: =SUMIF(Data!$G$2:$G$1501,"Retail",Data!$D$2:$D$1501) | J3: Cash | K3: =SUMIF(Data!$K$2:$K$1501,"Cash",Data!$J$2:$J$1501)
A4: East | B4: =SUMIF(Data!$B$2:$B$1501,"East",Data!$J$2:$J$1501) | D4: Desk | E4: =SUMIF(Data!$C$2:$C$1501,"Desk",Data!$J$2:$J$1501) | G4: Wholesale | H4: =SUMIF(Data!$G$2:$G$1501,"Wholesale",Data!$D$2:$D$1501) | J4: Credit Card | K4: =SUMIF(Data!$K$2:$K$1501,"Credit Card",Data!$J$2:$J$1501)
A5: North | B5: =SUMIF(Data!$B$2:$B$1501,"North",Data!$J$2:$J$1501) | D5: Laptop | E5: =SUMIF(Data!$C$2:$C$1501,"Laptop",Data!$J$2:$J$1501) | J5: Debit Card | K5: =SUMIF(Data!$K$2:$K$1501,"Debit Card",Data!$J$2:$J$1501)
A6: South | B6: =SUMIF(Data!$B$2:$B$1501,"South",Data!$J$2:$J$1501) | D6: Monitor | E6: =SUMIF(Data!$C$2:$C$1501,"Monitor",Data!$J$2:$J$1501) | J6: Gift Card | K6: =SUMIF(Data!$K$2:$K$1501,"Gift Card",Data!$J$2:$J$1501)
A7: West | B7: =SUMIF(Data!$B$2:$B$1501,"West",Data!$J$2:$J$1501) | D7: Phone | E7: =SUMIF(Data!$C$2:$C$1501,"Phone",Data!$J$2:$J$1501) | J7: Online | K7: =SUMIF(Data!$K$2:$K$1501,"Online",Data!$J$2:$J$1501)
D8: Printer | E8: =SUMIF(Data!$C$2:$C$1501,"Printer",Data!$J$2:$J$1501)
D9: Tablet | E9: =SUMIF(Data!$C$2:$C$1501,"Tablet",Data!$J$2:$J$1501)
A12: 5. Store X=Store Y=Sales | D12: 6. Salesperson X=Salesperson Y=Sales | G12: 7. Monthly Sales X=YearMonth Y=Sales | L12: 8. Promo X=Promo Y=Sales
A13: Store | B13: Sales | D13: Salesperson | E13: Sales | G13: YearMonth | H13: Sales | I13: Qty | J13: Cumulative | L13: Promotion | M13: Sales | N13: Avg Discount
A14: Store A | B14: =SUMIF(Data!$F$2:$F$1501,"Store A",Data!$J$2:$J$1501) | D14: Alice | E14: =SUMIF(Data!$I$2:$I$1501,"Alice",Data!$J$2:$J$1501) | G14: 2023-01 | H14: =SUMIF(Data!$T$2:$T$1501,"2023-01",Data!$J$2:$J$1501) | I14: =SUMIF(Data!$T$2:$T$1501,"2023-01",Data!$D$2:$D$1501) | J14: =SUM($H$14:H14) | L14: FREESHIP | M14: =SUMIF(Data!$L$2:$L$1501,"FREESHIP",Data!$J$2:$J$1501) | N14: =AVERAGEIF(Data!$L$2:$L$1501,"FREESHIP",Data!$H$2:$H$1501)
A15: Store B | B15: =SUMIF(Data!$F$2:$F$1501,"Store B",Data!$J$2:$J$1501) | D15: Bob | E15: =SUMIF(Data!$I$2:$I$1501,"Bob",Data!$J$2:$J$1501) | G15: 2023-02 | H15: =SUMIF(Data!$T$2:$T$1501,"2023-02",Data!$J$2:$J$1501) | I15: =SUMIF(Data!$T$2:$T$1501,"2023-02",Data!$D$2:$D$1501) | J15: =SUM($H$14:H15) | L15: SAVE10 | M15: =SUMIF(Data!$L$2:$L$1501,"SAVE10",Data!$J$2:$J$1501) | N15: =AVERAGEIF(Data!$L$2:$L$1501,"SAVE10",Data!$H$2:$H$1501)
A16: Store C | B16: =SUMIF(Data!$F$2:$F$1501,"Store C",Data!$J$2:$J$1501) | D16: Carlos | E16: =SUMIF(Data!$I$2:$I$1501,"Carlos",Data!$J$2:$J$1501) | G16: 2023-03 | H16: =SUMIF(Data!$T$2:$T$1501,"2023-03",Data!$J$2:$J$1501) | I16: =SUMIF(Data!$T$2:$T$1501,"2023-03",Data!$D$2:$D$1501) | J16: =SUM($H$14:H16) | L16: WINTER15 | M16: =SUMIF(Data!$L$2:$L$1501,"WINTER15",Data!$J$2:$J$1501) | N16: =AVERAGEIF(Data!$L$2:$L$1501,"WINTER15",Data!$H$2:$H$1501)
A17: Store D | B17: =SUMIF(Data!$F$2:$F$1501,"Store D",Data!$J$2:$J$1501) | D17: Diana | E17: =SUMIF(Data!$I$2:$I$1501,"Diana",Data!$J$2:$J$1501) | G17: 2023-04 | H17: =SUMIF(Data!$T$2:$T$1501,"2023-04",Data!$J$2:$J$1501) | I17: =SUMIF(Data!$T$2:$T$1501,"2023-04",Data!$D$2:$D$1501) | J17: =SUM($H$14:H17)
D18: Eva | E18: =SUMIF(Data!$I$2:$I$1501,"Eva",Data!$J$2:$J$1501) | G18: 2023-05 | H18: =SUMIF(Data!$T$2:$T$1501,"2023-05",Data!$J$2:$J$1501) | I18: =SUMIF(Data!$T$2:$T$1501,"2023-05",Data!$D$2:$D$1501) | J18: =SUM($H$14:H18)
D19: Frank | E19: =SUMIF(Data!$I$2:$I$1501,"Frank",Data!$J$2:$J$1501) | G19: 2023-06 | H19: =SUMIF(Data!$T$2:$T$1501,"2023-06",Data!$J$2:$J$1501) | I19: =SUMIF(Data!$T$2:$T$1501,"2023-06",Data!$D$2:$D$1501) | J19: =SUM($H$14:H19)
G20: 2023-07 | H20: =SUMIF(Data!$T$2:$T$1501,"2023-07",Data!$J$2:$J$1501) | I20: =SUMIF(Data!$T$2:$T$1501,"2023-07",Data!$D$2:$D$1501) | J20: =SUM($H$14:H20)
G21: 2023-08 | H21: =SUMIF(Data!$T$2:$T$1501,"2023-08",Data!$J$2:$J$1501) | I21: =SUMIF(Data!$T$2:$T$1501,"2023-08",Data!$D$2:$D$1501) | J21: =SUM($H$14:H21)
G22: 2023-09 | H22: =SUMIF(Data!$T$2:$T$1501,"2023-09",Data!$J$2:$J$1501) | I22: =SUMIF(Data!$T$2:$T$1501,"2023-09",Data!$D$2:$D$1501) | J22: =SUM($H$14:H22)
G23: 2023-10 | H23: =SUMIF(Data!$T$2:$T$1501,"2023-10",Data!$J$2:$J$1501) | I23: =SUMIF(Data!$T$2:$T$1501,"2023-10",Data!$D$2:$D$1501) | J23: =SUM($H$14:H23)
G24: 2023-11 | H24: =SUMIF(Data!$T$2:$T$1501,"2023-11",Data!$J$2:$J$1501) | I24: =SUMIF(Data!$T$2:$T$1501,"2023-11",Data!$D$2:$D$1501) | J24: =SUM($H$14:H24)
G25: 2023-12 | H25: =SUMIF(Data!$T$2:$T$1501,"2023-12",Data!$J$2:$J$1501) | I25: =SUMIF(Data!$T$2:$T$1501,"2023-12",Data!$D$2:$D$1501) | J25: =SUM($H$14:H25)
G26: 2024-01 | H26: =SUMIF(Data!$T$2:$T$1501,"2024-01",Data!$J$2:$J$1501) | I26: =SUMIF(Data!$T$2:$T$1501,"2024-01",Data!$D$2:$D$1501) | J26: =SUM($H$14:H26)
G27: 2024-02 | H27: =SUMIF(Data!$T$2:$T$1501,"2024-02",Data!$J$2:$J$1501) | I27: =SUMIF(Data!$T$2:$T$1501,"2024-02",Data!$D$2:$D$1501) | J27: =SUM($H$14:H27)
G28: 2024-03 | H28: =SUMIF(Data!$T$2:$T$1501,"2024-03",Data!$J$2:$J$1501) | I28: =SUMIF(Data!$T$2:$T$1501,"2024-03",Data!$D$2:$D$1501) | J28: =SUM($H$14:H28)
G29: 2024-04 | H29: =SUMIF(Data!$T$2:$T$1501,"2024-04",Data!$J$2:$J$1501) | I29: =SUMIF(Data!$T$2:$T$1501,"2024-04",Data!$D$2:$D$1501) | J29: =SUM($H$14:H29)
G30: 2024-05 | H30: =SUMIF(Data!$T$2:$T$1501,"2024-05",Data!$J$2:$J$1501) | I30: =SUMIF(Data!$T$2:$T$1501,"2024-05",Data!$D$2:$D$1501) | J30: =SUM($H$14:H30)
G31: 2024-06 | H31: =SUMIF(Data!$T$2:$T$1501,"2024-06",Data!$J$2:$J$1501) | I31: =SUMIF(Data!$T$2:$T$1501,"2024-06",Data!$D$2:$D$1501) | J31: =SUM($H$14:H31)
G32: 2024-07 | H32: =SUMIF(Data!$T$2:$T$1501,"2024-07",Data!$J$2:$J$1501) | I32: =SUMIF(Data!$T$2:$T$1501,"2024-07",Data!$D$2:$D$1501) | J32: =SUM($H$14:H32)
G33: 2024-08 | H33: =SUMIF(Data!$T$2:$T$1501,"2024-08",Data!$J$2:$J$1501) | I33: =SUMIF(Data!$T$2:$T$1501,"2024-08",Data!$D$2:$D$1501) | J33: =SUM($H$14:H33)
G34: 2024-09 | H34: =SUMIF(Data!$T$2:$T$1501,"2024-09",Data!$J$2:$J$1501) | I34: =SUMIF(Data!$T$2:$T$1501,"2024-09",Data!$D$2:$D$1501) | J34: =SUM($H$14:H34)
G35: 2024-10 | H35: =SUMIF(Data!$T$2:$T$1501,"2024-10",Data!$J$2:$J$1501) | I35: =SUMIF(Data!$T$2:$T$1501,"2024-10",Data!$D$2:$D$1501) | J35: =SUM($H$14:H35)
G36: 2024-11 | H36: =SUMIF(Data!$T$2:$T$1501,"2024-11",Data!$J$2:$J$1501) | I36: =SUMIF(Data!$T$2:$T$1501,"2024-11",Data!$D$2:$D$1501) | J36: =SUM($H$14:H36)
G37: 2024-12 | H37: =SUMIF(Data!$T$2:$T$1501,"2024-12",Data!$J$2:$J$1501) | I37: =SUMIF(Data!$T$2:$T$1501,"2024-12",Data!$D$2:$D$1501) | J37: =SUM($H$14:H37)
G38: 2025-01 | H38: =SUMIF(Data!$T$2:$T$1501,"2025-01",Data!$J$2:$J$1501) | I38: =SUMIF(Data!$T$2:$T$1501,"2025-01",Data!$D$2:$D$1501) | J38: =SUM($H$14:H38)
G39: 2025-02 | H39: =SUMIF(Data!$T$2:$T$1501,"2025-02",Data!$J$2:$J$1501) | I39: =SUMIF(Data!$T$2:$T$1501,"2025-02",Data!$D$2:$D$1501) | J39: =SUM($H$14:H39)
G40: Scatter Sample X=UnitPrice Y=Qty | H40: =SUMIF(Data!$T$2:$T$1501,"2025-03",Data!$J$2:$J$1501) | I40: =SUMIF(Data!$T$2:$T$1501,"2025-03",Data!$D$2:$D$1501) | J40: =SUM($H$14:H40)
G41: UnitPrice | H41: Quantity | I41: =SUMIF(Data!$T$2:$T$1501,"2025-04",Data!$D$2:$D$1501) | J41: =SUM($H$14:H41)
G42: 423.64 | H42: 13 | I42: =SUMIF(Data!$T$2:$T$1501,"2025-05",Data!$D$2:$D$1501) | J42: =SUM($H$14:H42)
...

Sheet Instructions
A1: AUDITED 5.2 - ZERO REF - PLAIN RANGE FORMULAS
A3: Previous used SalesData[Region] structured refs - some Excel versions show #REF if table not recalculated
A4: Now all formulas use plain ranges: =SUMIF(Data!B2:B1501,"East",Data!J2:J1501) - never #REF
A5: YearMonth helper column T in Data sheet = date formatted yyyy-mm, used for monthly charts
A6: KPI cards: =SUM(Data!J2:J1501) etc - connected, if Data changes, dashboard updates
A7: Charts point to Analytics which has plain SUMIF formulas - all connected
A8: Full Screen: Press Alt+W then L (View>Full Screen) or add VBA: Sub ToggleFullScreen() Application.DisplayFullScreen = Not Application.DisplayFullScreen: End Sub
A9: Neat arrangement: 3 charts per row, 13 width, colorful, header full width
